2020-05-27 17:05:10,432 ERROR: Exception on /reset_password_request [POST] [in /Users/heliu/anaconda3/envs/venv/lib/python3.8/site-packages/flask/app.py:1891]
Traceback (most recent call last):
  File "/Users/heliu/anaconda3/envs/venv/lib/python3.8/site-packages/flask/app.py", line 2447, in wsgi_app
    response = self.full_dispatch_request()
  File "/Users/heliu/anaconda3/envs/venv/lib/python3.8/site-packages/flask/app.py", line 1952, in full_dispatch_request
    rv = self.handle_user_exception(e)
  File "/Users/heliu/anaconda3/envs/venv/lib/python3.8/site-packages/flask/app.py", line 1821, in handle_user_exception
    reraise(exc_type, exc_value, tb)
  File "/Users/heliu/anaconda3/envs/venv/lib/python3.8/site-packages/flask/_compat.py", line 39, in reraise
    raise value
  File "/Users/heliu/anaconda3/envs/venv/lib/python3.8/site-packages/flask/app.py", line 1950, in full_dispatch_request
    rv = self.dispatch_request()
  File "/Users/heliu/anaconda3/envs/venv/lib/python3.8/site-packages/flask/app.py", line 1936, in dispatch_request
    return self.view_functions[rule.endpoint](**req.view_args)
  File "/Users/heliu/flask/microblog/app/routes.py", line 173, in reset_password_request
    send_password_reset_email(user)
  File "/Users/heliu/flask/microblog/app/email.py", line 13, in send_password_reset_email
    send_email('[Microblog] Reset Your Password',
  File "/Users/heliu/flask/microblog/app/email.py", line 9, in send_email
    mail.send(msg)
  File "/Users/heliu/anaconda3/envs/venv/lib/python3.8/site-packages/flask_mail.py", line 491, in send
    with self.connect() as connection:
  File "/Users/heliu/anaconda3/envs/venv/lib/python3.8/site-packages/flask_mail.py", line 144, in __enter__
    self.host = self.configure_host()
  File "/Users/heliu/anaconda3/envs/venv/lib/python3.8/site-packages/flask_mail.py", line 158, in configure_host
    host = smtplib.SMTP(self.mail.server, self.mail.port)
  File "/Users/heliu/anaconda3/envs/venv/lib/python3.8/smtplib.py", line 253, in __init__
    (code, msg) = self.connect(host, port)
  File "/Users/heliu/anaconda3/envs/venv/lib/python3.8/smtplib.py", line 341, in connect
    (code, msg) = self.getreply()
  File "/Users/heliu/anaconda3/envs/venv/lib/python3.8/smtplib.py", line 398, in getreply
    raise SMTPServerDisconnected("Connection unexpectedly closed")
smtplib.SMTPServerDisconnected: Connection unexpectedly closed
2020-05-27 18:01:02,372 INFO: Microblog startup [in /Users/heliu/flask/microblog/app/__init__.py:45]
2020-05-27 18:01:22,069 ERROR: Exception on /reset_password_request [POST] [in /Users/heliu/anaconda3/envs/venv/lib/python3.8/site-packages/flask/app.py:1891]
Traceback (most recent call last):
  File "/Users/heliu/anaconda3/envs/venv/lib/python3.8/site-packages/flask/app.py", line 2447, in wsgi_app
    response = self.full_dispatch_request()
  File "/Users/heliu/anaconda3/envs/venv/lib/python3.8/site-packages/flask/app.py", line 1952, in full_dispatch_request
    rv = self.handle_user_exception(e)
  File "/Users/heliu/anaconda3/envs/venv/lib/python3.8/site-packages/flask/app.py", line 1821, in handle_user_exception
    reraise(exc_type, exc_value, tb)
  File "/Users/heliu/anaconda3/envs/venv/lib/python3.8/site-packages/flask/_compat.py", line 39, in reraise
    raise value
  File "/Users/heliu/anaconda3/envs/venv/lib/python3.8/site-packages/flask/app.py", line 1950, in full_dispatch_request
    rv = self.dispatch_request()
  File "/Users/heliu/anaconda3/envs/venv/lib/python3.8/site-packages/flask/app.py", line 1936, in dispatch_request
    return self.view_functions[rule.endpoint](**req.view_args)
  File "/Users/heliu/flask/microblog/app/routes.py", line 173, in reset_password_request
    send_password_reset_email(user)
  File "/Users/heliu/flask/microblog/app/email.py", line 15, in send_password_reset_email
    send_email('[Microblog] Reset Your Password',
  File "/Users/heliu/flask/microblog/app/email.py", line 11, in send_email
    mail.send(msg)
  File "/Users/heliu/anaconda3/envs/venv/lib/python3.8/site-packages/flask_mail.py", line 491, in send
    with self.connect() as connection:
  File "/Users/heliu/anaconda3/envs/venv/lib/python3.8/site-packages/flask_mail.py", line 144, in __enter__
    self.host = self.configure_host()
  File "/Users/heliu/anaconda3/envs/venv/lib/python3.8/site-packages/flask_mail.py", line 158, in configure_host
    host = smtplib.SMTP(self.mail.server, self.mail.port)
  File "/Users/heliu/anaconda3/envs/venv/lib/python3.8/smtplib.py", line 253, in __init__
    (code, msg) = self.connect(host, port)
  File "/Users/heliu/anaconda3/envs/venv/lib/python3.8/smtplib.py", line 341, in connect
    (code, msg) = self.getreply()
  File "/Users/heliu/anaconda3/envs/venv/lib/python3.8/smtplib.py", line 398, in getreply
    raise SMTPServerDisconnected("Connection unexpectedly closed")
smtplib.SMTPServerDisconnected: Connection unexpectedly closed
2020-05-27 18:07:35,047 INFO: Microblog startup [in /Users/heliu/flask/microblog/app/__init__.py:45]
2020-05-27 18:07:53,599 INFO: Microblog startup [in /Users/heliu/flask/microblog/app/__init__.py:45]
2020-05-27 18:08:21,216 INFO: Microblog startup [in /Users/heliu/flask/microblog/app/__init__.py:45]
2020-05-27 18:11:18,046 ERROR: Exception on /reset_password/eyJ0eXAiOiJKV1QiLCJhbGciOiJIUzI1NiJ9.eyJyZXNldF9wYXNzd29yZCI6NSwiZXhwIjoxNTkwNjI4NzEyLjEyNjYxNzJ9.dP8206b3iQMgRVTZl526rRFIK8Y_tyiewBS3Kb5lalc [GET] [in /Users/heliu/anaconda3/envs/venv/lib/python3.8/site-packages/flask/app.py:1891]
Traceback (most recent call last):
  File "/Users/heliu/anaconda3/envs/venv/lib/python3.8/site-packages/flask/app.py", line 2447, in wsgi_app
    response = self.full_dispatch_request()
  File "/Users/heliu/anaconda3/envs/venv/lib/python3.8/site-packages/flask/app.py", line 1952, in full_dispatch_request
    rv = self.handle_user_exception(e)
  File "/Users/heliu/anaconda3/envs/venv/lib/python3.8/site-packages/flask/app.py", line 1821, in handle_user_exception
    reraise(exc_type, exc_value, tb)
  File "/Users/heliu/anaconda3/envs/venv/lib/python3.8/site-packages/flask/_compat.py", line 39, in reraise
    raise value
  File "/Users/heliu/anaconda3/envs/venv/lib/python3.8/site-packages/flask/app.py", line 1950, in full_dispatch_request
    rv = self.dispatch_request()
  File "/Users/heliu/anaconda3/envs/venv/lib/python3.8/site-packages/flask/app.py", line 1936, in dispatch_request
    return self.view_functions[rule.endpoint](**req.view_args)
  File "/Users/heliu/flask/microblog/app/routes.py", line 186, in reset_password
    form = ResetPasswordForm()
NameError: name 'ResetPasswordForm' is not defined
2020-05-27 18:12:08,736 INFO: Microblog startup [in /Users/heliu/flask/microblog/app/__init__.py:45]
2020-05-27 18:12:25,699 INFO: Microblog startup [in /Users/heliu/flask/microblog/app/__init__.py:45]
2020-05-27 18:12:39,170 ERROR: Exception on /reset_password/eyJ0eXAiOiJKV1QiLCJhbGciOiJIUzI1NiJ9.eyJyZXNldF9wYXNzd29yZCI6NSwiZXhwIjoxNTkwNjI4NzEyLjEyNjYxNzJ9.dP8206b3iQMgRVTZl526rRFIK8Y_tyiewBS3Kb5lalc [GET] [in /Users/heliu/anaconda3/envs/venv/lib/python3.8/site-packages/flask/app.py:1891]
Traceback (most recent call last):
  File "/Users/heliu/anaconda3/envs/venv/lib/python3.8/site-packages/flask/app.py", line 2447, in wsgi_app
    response = self.full_dispatch_request()
  File "/Users/heliu/anaconda3/envs/venv/lib/python3.8/site-packages/flask/app.py", line 1952, in full_dispatch_request
    rv = self.handle_user_exception(e)
  File "/Users/heliu/anaconda3/envs/venv/lib/python3.8/site-packages/flask/app.py", line 1821, in handle_user_exception
    reraise(exc_type, exc_value, tb)
  File "/Users/heliu/anaconda3/envs/venv/lib/python3.8/site-packages/flask/_compat.py", line 39, in reraise
    raise value
  File "/Users/heliu/anaconda3/envs/venv/lib/python3.8/site-packages/flask/app.py", line 1950, in full_dispatch_request
    rv = self.dispatch_request()
  File "/Users/heliu/anaconda3/envs/venv/lib/python3.8/site-packages/flask/app.py", line 1936, in dispatch_request
    return self.view_functions[rule.endpoint](**req.view_args)
  File "/Users/heliu/flask/microblog/app/routes.py", line 192, in reset_password
    return render_template('reset_password.html', form = form)
  File "/Users/heliu/anaconda3/envs/venv/lib/python3.8/site-packages/flask/templating.py", line 137, in render_template
    return _render(
  File "/Users/heliu/anaconda3/envs/venv/lib/python3.8/site-packages/flask/templating.py", line 120, in _render
    rv = template.render(context)
  File "/Users/heliu/anaconda3/envs/venv/lib/python3.8/site-packages/jinja2/environment.py", line 1090, in render
    self.environment.handle_exception()
  File "/Users/heliu/anaconda3/envs/venv/lib/python3.8/site-packages/jinja2/environment.py", line 832, in handle_exception
    reraise(*rewrite_traceback_stack(source=source))
  File "/Users/heliu/anaconda3/envs/venv/lib/python3.8/site-packages/jinja2/_compat.py", line 28, in reraise
    raise value.with_traceback(tb)
  File "/Users/heliu/flask/microblog/app/templates/reset_password.html", line 1, in top-level template code
    {% extends "base.html" %}
  File "/Users/heliu/flask/microblog/app/templates/base.html", line 30, in top-level template code
    {% block content %} {% endblock %}
  File "/Users/heliu/flask/microblog/app/templates/reset_password.html", line 9, in block "content"
    {{ form.password.size(32) }}<br>
jinja2.exceptions.UndefinedError: 'wtforms.fields.simple.PasswordField object' has no attribute 'size'
2020-05-27 18:14:18,524 INFO: Microblog startup [in /Users/heliu/flask/microblog/app/__init__.py:45]
