2020-05-27 09:54:55,876 ERROR: Exception on / [GET] [in /Users/heliu/anaconda3/envs/venv/lib/python3.8/site-packages/flask/app.py:1891]
Traceback (most recent call last):
  File "/Users/heliu/anaconda3/envs/venv/lib/python3.8/site-packages/flask/app.py", line 2447, in wsgi_app
    response = self.full_dispatch_request()
  File "/Users/heliu/anaconda3/envs/venv/lib/python3.8/site-packages/flask/app.py", line 1952, in full_dispatch_request
    rv = self.handle_user_exception(e)
  File "/Users/heliu/anaconda3/envs/venv/lib/python3.8/site-packages/flask/app.py", line 1821, in handle_user_exception
    reraise(exc_type, exc_value, tb)
  File "/Users/heliu/anaconda3/envs/venv/lib/python3.8/site-packages/flask/_compat.py", line 39, in reraise
    raise value
  File "/Users/heliu/anaconda3/envs/venv/lib/python3.8/site-packages/flask/app.py", line 1950, in full_dispatch_request
    rv = self.dispatch_request()
  File "/Users/heliu/anaconda3/envs/venv/lib/python3.8/site-packages/flask/app.py", line 1936, in dispatch_request
    return self.view_functions[rule.endpoint](**req.view_args)
  File "/Users/heliu/anaconda3/envs/venv/lib/python3.8/site-packages/flask_login/utils.py", line 272, in decorated_view
    return func(*args, **kwargs)
  File "/Users/heliu/flask/microblog/app/routes.py", line 23, in index
    return render_template('index.html', title = 'Home', form = form, posts = posts)
  File "/Users/heliu/anaconda3/envs/venv/lib/python3.8/site-packages/flask/templating.py", line 137, in render_template
    return _render(
  File "/Users/heliu/anaconda3/envs/venv/lib/python3.8/site-packages/flask/templating.py", line 120, in _render
    rv = template.render(context)
  File "/Users/heliu/anaconda3/envs/venv/lib/python3.8/site-packages/jinja2/environment.py", line 1090, in render
    self.environment.handle_exception()
  File "/Users/heliu/anaconda3/envs/venv/lib/python3.8/site-packages/jinja2/environment.py", line 832, in handle_exception
    reraise(*rewrite_traceback_stack(source=source))
  File "/Users/heliu/anaconda3/envs/venv/lib/python3.8/site-packages/jinja2/_compat.py", line 28, in reraise
    raise value.with_traceback(tb)
  File "/Users/heliu/flask/microblog/app/templates/index.html", line 1, in top-level template code
    {% extends "base.html" %}
  File "/Users/heliu/flask/microblog/app/templates/base.html", line 30, in top-level template code
    {% block content %} {% endblock %}
  File "/Users/heliu/flask/microblog/app/templates/index.html", line 20, in block "content"
    {% include '_post.html' %}
  File "/Users/heliu/flask/microblog/app/templates/_post.html", line 5, in top-level template code
    <a href="{{ url_for('user', username=post.auhor.username) }}">
  File "/Users/heliu/anaconda3/envs/venv/lib/python3.8/site-packages/jinja2/environment.py", line 471, in getattr
    return getattr(obj, attribute)
jinja2.exceptions.UndefinedError: 'app.models.Post object' has no attribute 'auhor'
2020-05-27 10:25:01,226 INFO: Microblog startup [in /Users/heliu/flask/microblog/app/__init__.py:43]
2020-05-27 12:44:57,403 INFO: Microblog startup [in /Users/heliu/flask/microblog/app/__init__.py:43]
2020-05-27 13:17:59,376 INFO: Microblog startup [in /Users/heliu/flask/microblog/app/__init__.py:43]
2020-05-27 13:18:16,837 ERROR: Exception on /index [GET] [in /Users/heliu/anaconda3/envs/venv/lib/python3.8/site-packages/flask/app.py:1891]
Traceback (most recent call last):
  File "/Users/heliu/anaconda3/envs/venv/lib/python3.8/site-packages/flask/app.py", line 2447, in wsgi_app
    response = self.full_dispatch_request()
  File "/Users/heliu/anaconda3/envs/venv/lib/python3.8/site-packages/flask/app.py", line 1952, in full_dispatch_request
    rv = self.handle_user_exception(e)
  File "/Users/heliu/anaconda3/envs/venv/lib/python3.8/site-packages/flask/app.py", line 1821, in handle_user_exception
    reraise(exc_type, exc_value, tb)
  File "/Users/heliu/anaconda3/envs/venv/lib/python3.8/site-packages/flask/_compat.py", line 39, in reraise
    raise value
  File "/Users/heliu/anaconda3/envs/venv/lib/python3.8/site-packages/flask/app.py", line 1950, in full_dispatch_request
    rv = self.dispatch_request()
  File "/Users/heliu/anaconda3/envs/venv/lib/python3.8/site-packages/flask/app.py", line 1936, in dispatch_request
    return self.view_functions[rule.endpoint](**req.view_args)
  File "/Users/heliu/anaconda3/envs/venv/lib/python3.8/site-packages/flask_login/utils.py", line 272, in decorated_view
    return func(*args, **kwargs)
  File "/Users/heliu/flask/microblog/app/routes.py", line 27, in index
    prev_url = url_for('index', page = posts.prev_num) if posts.has_prev else none
NameError: name 'none' is not defined
2020-05-27 13:23:25,694 INFO: Microblog startup [in /Users/heliu/flask/microblog/app/__init__.py:43]
2020-05-27 15:21:15,231 INFO: Microblog startup [in /Users/heliu/flask/microblog/app/__init__.py:45]
2020-05-27 15:25:44,142 INFO: Microblog startup [in /Users/heliu/flask/microblog/app/__init__.py:45]
2020-05-27 15:33:58,974 INFO: Microblog startup [in /Users/heliu/flask/microblog/app/__init__.py:45]
2020-05-27 15:42:51,219 INFO: Microblog startup [in /Users/heliu/flask/microblog/app/__init__.py:45]
2020-05-27 15:45:40,576 INFO: Microblog startup [in /Users/heliu/flask/microblog/app/__init__.py:45]
2020-05-27 16:38:36,949 INFO: Microblog startup [in /Users/heliu/flask/microblog/app/__init__.py:45]
2020-05-27 16:42:55,733 ERROR: Exception on /reset_password_request [POST] [in /Users/heliu/anaconda3/envs/venv/lib/python3.8/site-packages/flask/app.py:1891]
Traceback (most recent call last):
  File "/Users/heliu/anaconda3/envs/venv/lib/python3.8/site-packages/flask/app.py", line 2447, in wsgi_app
    response = self.full_dispatch_request()
  File "/Users/heliu/anaconda3/envs/venv/lib/python3.8/site-packages/flask/app.py", line 1952, in full_dispatch_request
    rv = self.handle_user_exception(e)
  File "/Users/heliu/anaconda3/envs/venv/lib/python3.8/site-packages/flask/app.py", line 1821, in handle_user_exception
    reraise(exc_type, exc_value, tb)
  File "/Users/heliu/anaconda3/envs/venv/lib/python3.8/site-packages/flask/_compat.py", line 39, in reraise
    raise value
  File "/Users/heliu/anaconda3/envs/venv/lib/python3.8/site-packages/flask/app.py", line 1950, in full_dispatch_request
    rv = self.dispatch_request()
  File "/Users/heliu/anaconda3/envs/venv/lib/python3.8/site-packages/flask/app.py", line 1936, in dispatch_request
    return self.view_functions[rule.endpoint](**req.view_args)
  File "/Users/heliu/flask/microblog/app/routes.py", line 173, in reset_password_request
    send_password_reset_email(user)
  File "/Users/heliu/flask/microblog/app/email.py", line 16, in send_password_reset_email
    text_body = render_template('email/reset_password,txt', user = user, token = token),
  File "/Users/heliu/anaconda3/envs/venv/lib/python3.8/site-packages/flask/templating.py", line 138, in render_template
    ctx.app.jinja_env.get_or_select_template(template_name_or_list),
  File "/Users/heliu/anaconda3/envs/venv/lib/python3.8/site-packages/jinja2/environment.py", line 930, in get_or_select_template
    return self.get_template(template_name_or_list, parent, globals)
  File "/Users/heliu/anaconda3/envs/venv/lib/python3.8/site-packages/jinja2/environment.py", line 883, in get_template
    return self._load_template(name, self.make_globals(globals))
  File "/Users/heliu/anaconda3/envs/venv/lib/python3.8/site-packages/jinja2/environment.py", line 857, in _load_template
    template = self.loader.load(self, name, globals)
  File "/Users/heliu/anaconda3/envs/venv/lib/python3.8/site-packages/jinja2/loaders.py", line 115, in load
    source, filename, uptodate = self.get_source(environment, name)
  File "/Users/heliu/anaconda3/envs/venv/lib/python3.8/site-packages/flask/templating.py", line 60, in get_source
    return self._get_source_fast(environment, template)
  File "/Users/heliu/anaconda3/envs/venv/lib/python3.8/site-packages/flask/templating.py", line 89, in _get_source_fast
    raise TemplateNotFound(template)
jinja2.exceptions.TemplateNotFound: email/reset_password,txt
2020-05-27 16:44:13,378 INFO: Microblog startup [in /Users/heliu/flask/microblog/app/__init__.py:45]
2020-05-27 16:44:20,140 ERROR: Exception on /reset_password_request [POST] [in /Users/heliu/anaconda3/envs/venv/lib/python3.8/site-packages/flask/app.py:1891]
Traceback (most recent call last):
  File "/Users/heliu/anaconda3/envs/venv/lib/python3.8/site-packages/flask/app.py", line 2447, in wsgi_app
    response = self.full_dispatch_request()
  File "/Users/heliu/anaconda3/envs/venv/lib/python3.8/site-packages/flask/app.py", line 1952, in full_dispatch_request
    rv = self.handle_user_exception(e)
  File "/Users/heliu/anaconda3/envs/venv/lib/python3.8/site-packages/flask/app.py", line 1821, in handle_user_exception
    reraise(exc_type, exc_value, tb)
  File "/Users/heliu/anaconda3/envs/venv/lib/python3.8/site-packages/flask/_compat.py", line 39, in reraise
    raise value
  File "/Users/heliu/anaconda3/envs/venv/lib/python3.8/site-packages/flask/app.py", line 1950, in full_dispatch_request
    rv = self.dispatch_request()
  File "/Users/heliu/anaconda3/envs/venv/lib/python3.8/site-packages/flask/app.py", line 1936, in dispatch_request
    return self.view_functions[rule.endpoint](**req.view_args)
  File "/Users/heliu/flask/microblog/app/routes.py", line 173, in reset_password_request
    send_password_reset_email(user)
  File "/Users/heliu/flask/microblog/app/email.py", line 13, in send_password_reset_email
    send_email('[Microblog] Reset Your Password',
TypeError: send_email() got an unexpected keyword argument 'text_body'
2020-05-27 16:45:20,246 INFO: Microblog startup [in /Users/heliu/flask/microblog/app/__init__.py:45]
